Workbook

Sheet LEEME
A1: Análisis VTC · 1/09–7/10/2026
A2: Datos reales del conductor, anonimizados (sin pasajeros, matrículas ni direcciones).
A4: Hojas
A5: Resumen: indicadores y tablas con fórmulas (SUMIFS, COUNTIFS, AVERAGEIFS) y 3 gráficos.
A6: Escenarios: calcula tu neto por hora. Rellena las celdas AMARILLAS con tus costes.
A7: TD_DiaSemana, TD_Franjas, TD_Producto, TD_Mes_Pago: tablas dinámicas reales sobre la hoja Viajes.
A8: Viajes: 212 viajes (Tabla de Excel «tViajes»). Jornadas: 8 jornadas con horas de la app de la flota.
A10: Leyenda de colores
A11: Texto negro = fórmula · Texto azul = valor fijo/supuesto · Fondo amarillo = celda para que la rellenes tú.
A13: Cómo practicar con las tablas dinámicas
A14: 1. Haz clic dentro de una tabla dinámica → aparece el panel «Campos de tabla dinámica».
A15: 2. Arrastra campos a Filas, Columnas, Valores o Filtros. Prueba: Filas = semana_iso, Valores = Suma de importe_eur.
... A19: Limitaciones principales: solo 8 jornadas con horas; sin zonas, sin Uber, sin costes. Ver LIMITACIONES.md.

Sheet Resumen
A1: Resumen del análisis VTC (1/09–7/10/2026)
A2: Todas las cifras son FÓRMULAS sobre las hojas Viajes y Jornadas. Solo días completos (sin la noche del 31/08).
A4: Indicador | B4: Valor | C4: Cómo se calcula
A5: Días completos trabajados | B5: =SUMIFS(Viajes!$Q$2:$Q$213,Viajes!$P$2:$P$213,TRUE) | C5: Suma de la columna auxiliar es_primer_viaje_dia (1 por fecha) en días completos
A6: Viajes | B6: =COUNTIFS(Viajes!$P$2:$P$213,TRUE) | C6: COUNTIFS
A7: Ingresos totales | B7: =SUMIFS(Viajes!$K$2:$K$213,Viajes!$P$2:$P$213,TRUE) | C7: SUMIFS de importe_eur
A8: Ingreso medio por día | B8: =B7/B5 | C8: Ingresos ÷ días
A9: Viajes por día | B9: =B6/B5 | C9: Viajes ÷ días
A10: Importe medio por viaje con ingreso | B10: =AVERAGEIFS(Viajes!$K$2:$K$213,Viajes!$K$2:$K$213,">0",Viajes!$P$2:$P$213,TRUE) | C10: AVERAGEIFS, excluye los viajes de 0 €
A11: % de viajes a 0 € | B11: =COUNTIFS(Viajes!$K$2:$K$213,0,Viajes!$P$2:$P$213,TRUE)/B6 | C11: Probables cancelaciones
A12: % de viajes de 6 € exactos | B12: =COUNTIFS(Viajes!$K$2:$K$213,6,Viajes!$P$2:$P$213,TRUE)/B6 | C12: Probable importe mínimo
A13: € por hora de jornada (bruto) | B13: =SUMIFS(Jornadas!$M$2:$M$9,Jornadas!$L$2:$L$9,FALSE)/(SUMIFS(Jornadas!$K$2:$K$9,Jornadas!$L$2:$L$9,FALSE)/60) | C13: 7 jornadas con horas (sin el 02/10): Σ€ ÷ Σhoras
A14: € por hora efectiva (bruto) | B14: =SUMIFS(Jornadas!$M$2:$M$9,Jornadas!$L$2:$L$9,FALSE)/(SUMIFS(Jornadas!$J$2:$J$9,Jornadas!$L$2:$L$9,FALSE)/60) | C14: Igual, con el tiempo efectivo de la flota
A15: Minutos/día sin conducción efectiva | B15: =AVERAGEIFS(Jornadas!$F$2:$F$9,Jornadas!$L$2:$L$9,FALSE)+AVERAGEIFS(Jornadas!$G$2:$G$9,Jornadas!$L$2:$L$9,FALSE)+AVERAGEIFS(Jornadas!$H$2:$H$9,Jornadas!$L$2:$L$9,FALSE)+AVERAGEIFS(Jornadas!$I$2:$I$9,Jornadas!$L$2:$L$9,FALSE) | C15: Recarga + cuidado + no efectiva + sin clasificar
A17: Pregunta 2 · Ingresos por día de la semana
A18: Día | B18: Días trabajados | C18: Ingresos | D18: Ingreso medio por día
A19: lunes | B19: =SUMIFS(Viajes!$Q$2:$Q$213,Viajes!$F$2:$F$213,A19,Viajes!$P$2:$P$213,TRUE) | C19: =SUMIFS(Viajes!$K$2:$K$213,Viajes!$F$2:$F$213,A19,Viajes!$P$2:$P$213,TRUE) | D19: =C19/B19
A20: martes | B20: =SUMIFS(Viajes!$Q$2:$Q$213,Viajes!$F$2:$F$213,A20,Viajes!$P$2:$P$213,TRUE) | C20: =SUMIFS(Viajes!$K$2:$K$213,Viajes!$F$2:$F$213,A20,Viajes!$P$2:$P$213,TRUE) | D20: =C20/B20
A21: miércoles | B21: =SUMIFS(Viajes!$Q$2:$Q$213,Viajes!$F$2:$F$213,A21,Viajes!$P$2:$P$213,TRUE) | C21: =SUMIFS(Viajes!$K$2:$K$213,Viajes!$F$2:$F$213,A21,Viajes!$P$2:$P$213,TRUE) | D21: =C21/B21
A22: jueves | B22: =SUMIFS(Viajes!$Q$2:$Q$213,Viajes!$F$2:$F$213,A22,Viajes!$P$2:$P$213,TRUE) | C22: =SUMIFS(Viajes!$K$2:$K$213,Viajes!$F$2:$F$213,A22,Viajes!$P$2:$P$213,TRUE) | D22: =C22/B22
A23: viernes | B23: =SUMIFS(Viajes!$Q$2:$Q$213,Viajes!$F$2:$F$213,A23,Viajes!$P$2:$P$213,TRUE) | C23: =SUMIFS(Viajes!$K$2:$K$213,Viajes!$F$2:$F$213,A23,Viajes!$P$2:$P$213,TRUE) | D23: =C23/B23
A26: Pregunta 2 · Franjas horarias (hora de inicio del viaje)
A27: Franja | B27: Viajes | C27: Ingresos | D27: % viajes a 0 € | E27: € por hora trabajada*
A28: 06:00-06:59 | B28: =COUNTIFS(Viajes!$I$2:$I$213,A28,Viajes!$P$2:$P$213,TRUE) | C28: =SUMIFS(Viajes!$K$2:$K$213,Viajes!$I$2:$I$213,A28,Viajes!$P$2:$P$213,TRUE) | D28: =COUNTIFS(Viajes!$I$2:$I$213,A28,Viajes!$K$2:$K$213,0,Viajes!$P$2:$P$213,TRUE)/B28 | E28: 16.56
A29: 07:00-07:59 | B29: =COUNTIFS(Viajes!$I$2:$I$213,A29,Viajes!$P$2:$P$213,TRUE) | C29: =SUMIFS(Viajes!$K$2:$K$213,Viajes!$I$2:$I$213,A29,Viajes!$P$2:$P$213,TRUE) | D29: =COUNTIFS(Viajes!$I$2:$I$213,A29,Viajes!$K$2:$K$213,0,Viajes!$P$2:$P$213,TRUE)/B29 | E29: 17.72
A30: 08:00-08:59 | B30: =COUNTIFS(Viajes!$I$2:$I$213,A30,Viajes!$P$2:$P$213,TRUE) | C30: =SUMIFS(Viajes!$K$2:$K$213,Viajes!$I$2:$I$213,A30,Viajes!$P$2:$P$213,TRUE) | D30: =COUNTIFS(Viajes!$I$2:$I$213,A30,Viajes!$K$2:$K$213,0,Viajes!$P$2:$P$213,TRUE)/B30 | E30: 22.46
A31: 09:00-09:59 | B31: =COUNTIFS(Viajes!$I$2:$I$213,A31,Viajes!$P$2:$P$213,TRUE) | C31: =SUMIFS(Viajes!$K$2:$K$213,Viajes!$I$2:$I$213,A31,Viajes!$P$2:$P$213,TRUE) | D31: =COUNTIFS(Viajes!$I$2:$I$213,A31,Viajes!$K$2:$K$213,0,Viajes!$P$2:$P$213,TRUE)/B31 | E31: 17.92
A32: 10:00-10:59 | B32: =COUNTIFS(Viajes!$I$2:$I$213,A32,Viajes!$P$2:$P$213,TRUE) | C32: =SUMIFS(Viajes!$K$2:$K$213,Viajes!$I$2:$I$213,A32,Viajes!$P$2:$P$213,TRUE) | D32: =COUNTIFS(Viajes!$I$2:$I$213,A32,Viajes!$K$2:$K$213,0,Viajes!$P$2:$P$213,TRUE)/B32 | E32: 11.79
A33: 11:00-11:59 | B33: =COUNTIFS(Viajes!$I$2:$I$213,A33,Viajes!$P$2:$P$213,TRUE) | C33: =SUMIFS(Viajes!$K$2:$K$213,Viajes!$I$2:$I$213,A33,Viajes!$P$2:$P$213,TRUE) | D33: =COUNTIFS(Viajes!$I$2:$I$213,A33,Viajes!$K$2:$K$213,0,Viajes!$P$2:$P$213,TRUE)/B33 | E33: 8.65
A34: 12:00-12:59 | B34: =COUNTIFS(Viajes!$I$2:$I$213,A34,Viajes!$P$2:$P$213,TRUE) | C34: =SUMIFS(Viajes!$K$2:$K$213,Viajes!$I$2:$I$213,A34,Viajes!$P$2:$P$213,TRUE) | D34: =COUNTIFS(Viajes!$I$2:$I$213,A34,Viajes!$K$2:$K$213,0,Viajes!$P$2:$P$213,TRUE)/B34 | E34: 3.8
A35: * Valor fijo (texto azul) calculado en 02_analisis.ipynb: € de cada hora ÷ días en que trabajaste esa hora (entre tu primer y tu último viaje). No se puede hacer con una fórmula sencilla.
A37: Preguntas 3 y 5 · Tipos de servicio (no hay datos de Uber)
A38: Producto | B38: Viajes | C38: Ingresos | D38: Importe medio sin los de 0 €
A39: VTC | B39: =COUNTIFS(Viajes!$J$2:$J$213,A39,Viajes!$P$2:$P$213,TRUE) | C39: =SUMIFS(Viajes!$K$2:$K$213,Viajes!$J$2:$J$213,A39,Viajes!$P$2:$P$213,TRUE) | D39: =IFERROR(AVERAGEIFS(Viajes!$K$2:$K$213,Viajes!$J$2:$J$213,A39,Viajes!$K$2:$K$213,">0",Viajes!$P$2:$P$213,TRUE),0)
A40: VTC Airport | B40: =COUNTIFS(Viajes!$J$2:$J$213,A40,Viajes!$P$2:$P$213,TRUE) | C40: =SUMIFS(Viajes!$K$2:$K$213,Viajes!$J$2:$J$213,A40,Viajes!$P$2:$P$213,TRUE) | D40: =IFERROR(AVERAGEIFS(Viajes!$K$2:$K$213,Viajes!$J$2:$J$213,A40,Viajes!$K$2:$K$213,">0",Viajes!$P$2:$P$213,TRUE),0)
A41: VTC Eco | B41: =COUNTIFS(Viajes!$J$2:$J$213,A41,Viajes!$P$2:$P$213,TRUE) | C41: =SUMIFS(Viajes!$K$2:$K$213,Viajes!$J$2:$J$213,A41,Viajes!$P$2:$P$213,TRUE) | D41: =IFERROR(AVERAGEIFS(Viajes!$K$2:$K$213,Viajes!$J$2:$J$213,A41,Viajes!$K$2:$K$213,">0",Viajes!$P$2:$P$213,TRUE),0)
A42: VTC Prioritario | B42: =COUNTIFS(Viajes!$J$2:$J$213,A42,Viajes!$P$2:$P$213,TRUE) | C42: =SUMIFS(Viajes!$K$2:$K$213,Viajes!$J$2:$J$213,A42,Viajes!$P$2:$P$213,TRUE) | D42: =IFERROR(AVERAGEIFS(Viajes!$K$2:$K$213,Viajes!$J$2:$J$213,A42,Viajes!$K$2:$K$213,">0",Viajes!$P$2:$P$213,TRUE),0)
A43: Electric | B43: =COUNTIFS(Viajes!$J$2:$J$213,A43,Viajes!$P$2:$P$213,TRUE) | C43: =SUMIFS(Viajes!$K$2:$K$213,Viajes!$J$2:$J$213,A43,Viajes!$P$2:$P$213,TRUE) | D43: =IFERROR(AVERAGEIFS(Viajes!$K$2:$K$213,Viajes!$J$2:$J$213,A43,Viajes!$K$2:$K$213,">0",Viajes!$P$2:$P$213,TRUE),0)
A44: VTC Promo | B44: =COUNTIFS(Viajes!$J$2:$J$213,A44,Viajes!$P$2:$P$213,TRUE) | C44: =SUMIFS(Viajes!$K$2:$K$213,Viajes!$J$2:$J$213,A44,Viajes!$P$2:$P$213,TRUE) | D44: =IFERROR(AVERAGEIFS(Viajes!$K$2:$K$213,Viajes!$J$2:$J$213,A44,Viajes!$K$2:$K$213,">0",Viajes!$P$2:$P$213,TRUE),0)
A45: Envíos en coche | B45: =COUNTIFS(Viajes!$J$2:$J$213,A45,Viajes!$P$2:$P$213,TRUE) | C45: =SUMIFS(Viajes!$K$2:$K$213,Viajes!$J$2:$J$213,A45,Viajes!$P$2:$P$213,TRUE) | D45: =IFERROR(AVERAGEIFS(Viajes!$K$2:$K$213,Viajes!$J$2:$J$213,A45,Viajes!$K$2:$K$213,">0",Viajes!$P$2:$P$213,TRUE),0)
...

Sheet Escenarios
A1: Neto por hora: rellena TUS datos en las celdas amarillas
A2: Las capturas no muestran comisión ni costes, así que el neto no se puede calcular sin ti. No se ha inventado ningún coste: las celdas amarillas están vacías a propósito.
A3: Concepto | B3: Valor | C3: Nota
A4: € brutos por hora de jornada (de los datos) | B4: =Resumen!B13 | C4: Fórmula: enlaza con la hoja Resumen
A5: Horas por jornada (media de 7 jornadas) | B5: =AVERAGEIFS(Jornadas!$N$2:$N$9,Jornadas!$L$2:$L$9,FALSE) | C5: Fórmula: hoja Jornadas
A6: Días trabajados por semana (media) | B6: =Resumen!B5/6 | C6: 26 días ÷ 6 semanas con actividad (la 41 está a medias: subestima un poco)
A7: Horas por semana | B7: =B5*B6 | C7: Fórmula
A8: % de lo facturado que te queda (tras comisión y reparto con la flota) | C8: RELLENA (ej.: escribe 0,5 para 50 %)
A9: Costes fijos por semana (alquiler, cuota, seguro…) en € | C9: RELLENA (0 si no pagas)
A10: Energía/combustible por hora en € | C10: RELLENA (0 si lo paga la flota)
A11: Otros costes por hora en € | C11: RELLENA (0 si no hay)
A13: NETO por hora (€) | B13: =IF(COUNT(B8:B11)<4,"Rellena las 4 celdas amarillas",B4*B8-B9/B7-B10-B11)
A14: NETO por semana (€) | B14: =IF(ISNUMBER(B13),B13*B7,"")
A17: Tabla de escenarios HIPOTÉTICOS (no son datos): neto €/hora según % que te queda (filas) y costes fijos semanales (columnas), sin energía
A18: % que te queda \ costes fijos €/semana | B18: 0 | C18: 100 | D18: 200 | E18: 300
A19: 0.4 | B19: =$B$4*$A19-B$18/$B$7 | C19: =$B$4*$A19-C$18/$B$7 | D19: =$B$4*$A19-D$18/$B$7 | E19: =$B$4*$A19-E$18/$B$7
A20: 0.5 | B20: =$B$4*$A20-B$18/$B$7 | C20: =$B$4*$A20-C$18/$B$7 | D20: =$B$4*$A20-D$18/$B$7 | E20: =$B$4*$A20-E$18/$B$7
A21: 0.6 | B21: =$B$4*$A21-B$18/$B$7 | C21: =$B$4*$A21-C$18/$B$7 | D21: =$B$4*$A21-D$18/$B$7 | E21: =$B$4*$A21-E$18/$B$7
A22: 0.7 | B22: =$B$4*$A22-B$18/$B$7 | C22: =$B$4*$A22-C$18/$B$7 | D22: =$B$4*$A22-D$18/$B$7 | E22: =$B$4*$A22-E$18/$B$7
A23: 0.8 | B23: =$B$4*$A23-B$18/$B$7 | C23: =$B$4*$A23-C$18/$B$7 | D23: =$B$4*$A23-D$18/$B$7 | E23: =$B$4*$A23-E$18/$B$7
A24: 1 | B24: =$B$4*$A24-B$18/$B$7 | C24: =$B$4*$A24-C$18/$B$7 | D24: =$B$4*$A24-D$18/$B$7 | E24: =$B$4*$A24-E$18/$B$7
A26: Los valores de la cabecera de la tabla (texto azul) son supuestos para practicar; cámbialos si quieres.

Sheet TD_DiaSemana
F1: Tabla dinámica: ingresos y nº de viajes por día de la semana. Filtro: dia_completo = VERDADERO.
F2: Si sale vacía: pestaña Datos → Actualizar todo. Para practicar: arrastra otros campos en el panel de la derecha.

Sheet TD_Franjas
F1: Tabla dinámica: viajes, ingresos e importe medio por franja horaria. Filtro: dia_completo = VERDADERO.
F2: Si sale vacía: pestaña Datos → Actualizar todo. Para practicar: arrastra otros campos en el panel de la derecha.

Sheet TD_Producto
F1: Tabla dinámica: viajes, ingresos e importe medio por tipo de servicio (todos los viajes).
F2: Si sale vacía: pestaña Datos → Actualizar todo. Para practicar: arrastra otros campos en el panel de la derecha.

Sheet TD_Mes_Pago
F1: Tabla dinámica: ingresos por mes y método de pago. Compárala con la app: sep 1.620,42 € app + 122,61 € efectivo; oct 394,87 € + 57,79 €.
F2: Si sale vacía: pestaña Datos → Actualizar todo. Para practicar: arrastra otros campos en el panel de la derecha.

Sheet Viajes
A1: id_viaje | B1: fecha | C1: hora | D1: mes | E1: semana_iso | F1: dia_semana | G1: num_dia_semana | H1: hora_del_dia | I1: franja_horaria | J1: producto | K1: importe_eur | L1: metodo_pago | M1: sin_ingreso | N1: importe_6_exactos | O1: es_aeropuerto | P1: dia_completo | Q1: es_primer_viaje_dia
A2: V001 | B2: 46265 | C2: 21:23 | D2: 2026-08 | E2: 36 | F2: lunes | G2: 0 | H2: 21 | I2: 21:00-21:59 | J2: VTC | K2: 8.89 | L2: app | M2: FALSE | N2: FALSE | O2: FALSE | P2: FALSE | Q2: =IF(COUNTIF($B$2:B2,B2)=1,1,0)
A3: V002 | B3: 46265 | C3: 21:39 | D3: 2026-08 | E3: 36 | F3: lunes | G3: 0 | H3: 21 | I3: 21:00-21:59 | J3: VTC | K3: 8.15 | L3: app | M3: FALSE | N3: FALSE | O3: FALSE | P3: FALSE | Q3: =IF(COUNTIF($B$2:B3,B3)=1,1,0)
A4: V003 | B4: 46265 | C4: 21:59 | D4: 2026-08 | E4: 36 | F4: lunes | G4: 0 | H4: 21 | I4: 21:00-21:59 | J4: VTC Prioritario | K4: 16.6 | L4: app | M4: FALSE | N4: FALSE | O4: FALSE | P4: FALSE | Q4: =IF(COUNTIF($B$2:B4,B4)=1,1,0)
A5: V004 | B5: 46265 | C5: 22:17 | D5: 2026-08 | E5: 36 | F5: lunes | G5: 0 | H5: 22 | I5: 22:00-22:59 | J5: VTC | K5: 0 | L5: app | M5: TRUE | N5: FALSE | O5: FALSE | P5: FALSE | Q5: =IF(COUNTIF($B$2:B5,B5)=1,1,0)
A6: V005 | B6: 46265 | C6: 22:19 | D6: 2026-08 | E6: 36 | F6: lunes | G6: 0 | H6: 22 | I6: 22:00-22:59 | J6: VTC | K6: 15.85 | L6: app | M6: FALSE | N6: FALSE | O6: FALSE | P6: FALSE | Q6: =IF(COUNTIF($B$2:B6,B6)=1,1,0)
A7: V006 | B7: 46265 | C7: 22:45 | D7: 2026-08 | E7: 36 | F7: lunes | G7: 0 | H7: 22 | I7: 22:00-22:59 | J7: VTC Prioritario | K7: 10.71 | L7: app | M7: FALSE | N7: FALSE | O7: FALSE | P7: FALSE | Q7: =IF(COUNTIF($B$2:B7,B7)=1,1,0)
A8: V007 | B8: 46265 | C8: 23:13 | D8: 2026-08 | E8: 36 | F8: lunes | G8: 0 | H8: 23 | I8: 23:00-23:59 | J8: VTC Prioritario | K8: 8.04 | L8: app | M8: FALSE | N8: FALSE | O8: FALSE | P8: FALSE | Q8: =IF(COUNTIF($B$2:B8,B8)=1,1,0)
A9: V008 | B9: 46265 | C9: 23:26 | D9: 2026-08 | E9: 36 | F9: lunes | G9: 0 | H9: 23 | I9: 23:00-23:59 | J9: VTC Airport | K9: 16.03 | L9: app | M9: FALSE | N9: FALSE | O9: TRUE | P9: FALSE | Q9: =IF(COUNTIF($B$2:B9,B9)=1,1,0)
A10: V009 | B10: 46266 | C10: 08:10 | D10: 2026-09 | E10: 36 | F10: martes | G10: 1 | H10: 8 | I10: 08:00-08:59 | J10: Electric | K10: 12.73 | L10: app | M10: FALSE | N10: FALSE | O10: FALSE | P10: TRUE | Q10: =IF(COUNTIF($B$2:B10,B10)=1,1,0)
A11: V010 | B11: 46266 | C11: 08:43 | D11: 2026-09 | E11: 36 | F11: martes | G11: 1 | H11: 8 | I11: 08:00-08:59 | J11: VTC Prioritario | K11: 16.91 | L11: app | M11: FALSE | N11: FALSE | O11: FALSE | P11: TRUE | Q11: =IF(COUNTIF($B$2:B11,B11)=1,1,0)
A12: V011 | B12: 46266 | C12: 09:18 | D12: 2026-09 | E12: 36 | F12: martes | G12: 1 | H12: 9 | I12: 09:00-09:59 | J12: Envíos en coche | K12: 14.62 | L12: app | M12: FALSE | N12: FALSE | O12: FALSE | P12: TRUE | Q12: =IF(COUNTIF($B$2:B12,B12)=1,1,0)
A13: V012 | B13: 46266 | C13: 09:51 | D13: 2026-09 | E13: 36 | F13: martes | G13: 1 | H13: 9 | I13: 09:00-09:59 | J13: VTC | K13: 13.18 | L13: app | M13: FALSE | N13: FALSE | O13: FALSE | P13: TRUE | Q13: =IF(COUNTIF($B$2:B13,B13)=1,1,0)
... A213: V212 | B213: 46302 | C213: 10:37 | D213: 2026-10 | E213: 41 | F213: miércoles | G213: 2 | H213: 10 | I213: 10:00-10:59 | J213: VTC | K213: 23.37 | L213: app | M213: FALSE | N213: FALSE | O213: FALSE | P213: TRUE | Q213: =IF(COUNTIF($B$2:B213,B213)=1,1,0)

Sheet Jornadas
A1: fecha | B1: dia_semana | C1: inicio | D1: fin | E1: conduccion_efectiva_min | F1: recarga_electrica_min | G1: cuidado_vehiculo_min | H1: conduccion_no_efectiva_min | I1: sin_clasificar_min | J1: tiempo_efectivo_min | K1: tiempo_total_app_min | L1: jornada_anomala | M1: ingresos_eur | N1: horas_totales | O1: eur_por_hora_total | P1: eur_por_hora_efectiva
A2: 46293 | B2: lunes | C2: 06:15 | D2: 12:26 | E2: 314 | F2: 43 | G2: 10 | H2: 11 | I2: 46 | J2: 367 | K2: 424 | L2: FALSE | M2: =SUMIFS(Viajes!$K$2:$K$213,Viajes!$B$2:$B$213,A2) | N2: =K2/60 | O2: =M2/N2 | P2: =M2/(J2/60)
A3: 46294 | B3: martes | C3: 06:11 | D3: 12:17 | E3: 320 | F3: 33 | G3: 10 | H3: 4 | I3: 42 | J3: 363 | K3: 409 | L3: FALSE | M3: =SUMIFS(Viajes!$K$2:$K$213,Viajes!$B$2:$B$213,A3) | N3: =K3/60 | O3: =M3/N3 | P3: =M3/(J3/60)
A4: 46295 | B4: miércoles | C4: 06:17 | D4: 12:45 | E4: 351 | F4: 25 | G4: 10 | H4: 6 | I4: 31 | J4: 386 | K4: 422 | L4: FALSE | M4: =SUMIFS(Viajes!$K$2:$K$213,Viajes!$B$2:$B$213,A4) | N4: =K4/60 | O4: =M4/N4 | P4: =M4/(J4/60)
A5: 46296 | B5: jueves | C5: 06:23 | D5: 12:22 | E5: 313 | F5: 10 | G5: 10 | H5: 3 | I5: 43 | J5: 333 | K5: 378 | L5: FALSE | M5: =SUMIFS(Viajes!$K$2:$K$213,Viajes!$B$2:$B$213,A5) | N5: =K5/60 | O5: =M5/N5 | P5: =M5/(J5/60)
A6: 46297 | B6: viernes | C6: 06:30 | D6: 18:06 | E6: 302 | F6: 37 | G6: 10 | H6: 5 | I6: 389 | J6: 349 | K6: 742 | L6: TRUE | M6: =SUMIFS(Viajes!$K$2:$K$213,Viajes!$B$2:$B$213,A6) | N6: =K6/60 | O6: =M6/N6 | P6: =M6/(J6/60)
A7: 46300 | B7: lunes | C7: 06:20 | D7: 13:02 | E7: 312 | F7: 36 | G7: 10 | H7: 25 | I7: 65 | J7: 358 | K7: 447 | L7: FALSE | M7: =SUMIFS(Viajes!$K$2:$K$213,Viajes!$B$2:$B$213,A7) | N7: =K7/60 | O7: =M7/N7 | P7: =M7/(J7/60)
A8: 46301 | B8: martes | C8: 06:22 | D8: 13:04 | E8: 295 | F8: 55 | G8: 10 | H8: 0 | I8: 107 | J8: 360 | K8: 466 | L8: FALSE | M8: =SUMIFS(Viajes!$K$2:$K$213,Viajes!$B$2:$B$213,A8) | N8: =K8/60 | O8: =M8/N8 | P8: =M8/(J8/60)
A9: 46302 | B9: miércoles | C9: 06:21 | D9: 12:28 | E9: 306 | F9: 45 | G9: 10 | H9: 0 | I9: 61 | J9: 361 | K9: 422 | L9: FALSE | M9: =SUMIFS(Viajes!$K$2:$K$213,Viajes!$B$2:$B$213,A9) | N9: =K9/60 | O9: =M9/N9 | P9: =M9/(J9/60)
A11: Fuente: app de la flota («Detalle de jornada»). Columnas M–P son fórmulas. jornada_anomala = VERDADERO el 02/10 (probable jornada no cerrada).
